<?xml version="1.0" encoding="utf-8"?>
<robot xmlns:xacro="http://www.ros.org/wiki/xacro" name="hand">

  <xacro:property name="finger_mass" value="0.1" />
  <xacro:property name="gripper_mass"  value= "0.1" />

  <xacro:macro name="hand" params="connected_to:='' ns:='' rpy:='0 0 0' xyz:='0 0 0' ">

    <link name="${ns}_hand">
      <visual>
        <geometry>
          <mesh filename="package://franka_description/meshes/visual/hand.dae"/>
        </geometry>
      </visual>
      <collision>
        <geometry>
          <mesh filename="package://franka_description/meshes/collision/hand.stl"/>
        </geometry>
      </collision>
      <inertial>
        <origin xyz="0 0 0" rpy="0 0 0"/>
        <mass value="${gripper_mass}"/>
        <inertia ixx="0.002" ixy="0" ixz="0" iyy="0.0002" iyz="0" izz="0.0002"/>
      </inertial>
    </link>

    <joint name="${ns}_hand_joint" type="fixed">
      <parent link="${connected_to}"/>
      <child link="${ns}_hand"/>
      <origin xyz="${xyz}" rpy="${rpy}"/>
    </joint>

    <link name="${ns}_link9">
      <xacro:cylinder_inertial radius="0.06" length="0" mass="0">
        <origin xyz="0.0 0.0 0.0" rpy="0 0 0" />
      </xacro:cylinder_inertial>
    </link>

    <joint name="${ns}_joint9" type="fixed">
      <origin rpy="0 -1.57 0" xyz="0 0 0"/>
      <parent link="${ns}_hand"/>
      <child link="${ns}_link9"/>
      <axis xyz="0 0 0"/>
    </joint>

    <link name="${ns}_leftfinger">
      <visual>
        <geometry>
          <mesh filename="package://franka_description/meshes/visual/finger.dae"/>
        </geometry>
      </visual>
      <collision>
        <geometry>
          <mesh filename="package://franka_description/meshes/collision/finger.stl"/>
        </geometry>
      </collision>
      <inertial>
        <origin xyz="0 0 0" rpy="0 0 0"/>
        <mass value="${finger_mass}"/>
        <inertia ixx="0.002" ixy="0" ixz="0" iyy="0.0002" iyz="0" izz="0.0002"/>
      </inertial>
    </link>

    <link name="${ns}_rightfinger">
      <visual>
        <origin xyz="0 0 0" rpy="0 0 ${pi}"/>
        <geometry>
          <mesh filename="package://franka_description/meshes/visual/finger.dae"/>
        </geometry>
      </visual>
      <collision>
        <origin xyz="0 0 0" rpy="0 0 ${pi}"/>
        <geometry>
          <mesh filename="package://franka_description/meshes/collision/finger.stl"/>
        </geometry>
      </collision>
      <inertial>
        <origin xyz="0 0 0" rpy="0 0 0"/>
        <mass value="${finger_mass}"/>
        <inertia ixx="0.002" ixy="0" ixz="0" iyy="0.0002" iyz="0" izz="0.0002"/>
      </inertial>
    </link>

    <joint name="${ns}_finger_joint1" type="prismatic">
      <parent link="${ns}_hand"/>
      <child link="${ns}_leftfinger"/>
      <origin xyz="0 0 0.0584" rpy="0 0 0"/>
      <axis xyz="0 1 0"/>
      <limit effort="20" lower="0.0" upper="0.04" velocity="0.2"/>
    </joint>

    <joint name="${ns}_finger_joint2" type="prismatic">
      <parent link="${ns}_hand"/>
      <child link="${ns}_rightfinger"/>
      <origin xyz="0 0 0.0584" rpy="0 0 0"/>
      <axis xyz="0 -1 0"/>
      <limit effort="20" lower="0.0" upper="0.04" velocity="0.2"/>
    </joint>


    <transmission name="${ns}_finger_joint1_trans">
      <type>transmission_interface/SimpleTransmission</type>
      <joint name="${ns}_finger_joint1">
        <hardwareInterface>hardware_interface/EffortJointInterface</hardwareInterface>
      </joint>
      <actuator name="${ns}_finger_joint1_motor">
        <hardwareInterface>hardware_interface/EffortJointInterface</hardwareInterface>
        <mechanicalReduction>1</mechanicalReduction>
      </actuator>
    </transmission>

    <transmission name="${ns}_finger_joint2_trans">
      <type>transmission_interface/SimpleTransmission</type>
      <joint name="${ns}_finger_joint2">
        <hardwareInterface>hardware_interface/EffortJointInterface</hardwareInterface>
      </joint>
      <actuator name="${ns}_finger_joint2_motor">
        <hardwareInterface>hardware_interface/EffortJointInterface</hardwareInterface>
        <mechanicalReduction>1</mechanicalReduction>
      </actuator>
    </transmission>

  </xacro:macro>
</robot>
