<sdf version='1.6'>
  <world name='default'>
    <light name='sun' type='directional'>
      <cast_shadows>1</cast_shadows>
      <pose frame=''>0 0 10 0 -0 0</pose>
      <diffuse>0.8 0.8 0.8 1</diffuse>
      <specular>0.1 0.1 0.1 1</specular>
      <attenuation>
        <range>1000</range>
        <constant>0.9</constant>
        <linear>0.01</linear>
        <quadratic>0.001</quadratic>
      </attenuation>
      <direction>-0.5 0.5 -1</direction>
    </light>
    <model name='ground_plane'>
      <static>1</static>
      <link name='link'>
        <collision name='collision'>
          <geometry>
            <plane>
              <normal>0 0 1</normal>
              <size>100 100</size>
            </plane>
          </geometry>
          <surface>
            <friction>
              <ode>
                <mu>100</mu>
                <mu2>50</mu2>
              </ode>
              <torsional>
                <ode/>
              </torsional>
            </friction>
            <contact>
              <ode/>
            </contact>
            <bounce/>
          </surface>
          <max_contacts>10</max_contacts>
        </collision>
        <visual name='visual'>
          <cast_shadows>0</cast_shadows>
          <geometry>
            <plane>
              <normal>0 0 1</normal>
              <size>100 100</size>
            </plane>
          </geometry>
          <material>
            <script>
              <uri>file://media/materials/scripts/gazebo.material</uri>
              <name>Gazebo/Grey</name>
            </script>
          </material>
        </visual>
        <self_collide>0</self_collide>
        <kinematic>0</kinematic>
        <gravity>1</gravity>
      </link>
    </model>
    <gravity>0 0 -9.8</gravity>
    <magnetic_field>6e-06 2.3e-05 -4.2e-05</magnetic_field>
    <atmosphere type='adiabatic'/>
    <physics name='default_physics' default='0' type='ode'>
      <max_step_size>0.001</max_step_size>
      <real_time_factor>1</real_time_factor>
      <real_time_update_rate>1000</real_time_update_rate>
    </physics>
    <scene>
      <ambient>0.4 0.4 0.4 1</ambient>
      <background>0.7 0.7 0.7 1</background>
      <shadows>1</shadows>
    </scene>
    <spherical_coordinates>
      <surface_model>EARTH_WGS84</surface_model>
      <latitude_deg>0</latitude_deg>
      <longitude_deg>0</longitude_deg>
      <elevation>0</elevation>
      <heading_deg>0</heading_deg>
    </spherical_coordinates>
    <model name='robot'>
      <link name='camera_link'>
        <pose frame=''>0.6 0 0.8 0 1.57 0</pose>
        <inertial>
          <pose frame=''>0 0 0 0 -0 0</pose>
          <mass>0.2</mass>
          <inertia>
            <ixx>0.00058083</ixx>
            <ixy>0</ixy>
            <ixz>0</ixz>
            <iyy>3.0833e-05</iyy>
            <iyz>0</iyz>
            <izz>0.00059083</izz>
          </inertia>
        </inertial>
        <collision name='camera_link_collision'>
          <pose frame=''>-0.016 0 0 0 -0 0</pose>
          <geometry>
            <box>
              <size>0.036 0.18 0.04</size>
            </box>
          </geometry>
          <max_contacts>10</max_contacts>
          <surface>
            <contact>
              <ode/>
            </contact>
            <bounce/>
            <friction>
              <torsional>
                <ode/>
              </torsional>
              <ode/>
            </friction>
          </surface>
        </collision>
        <visual name='camera_link_visual'>
          <pose frame=''>0 0 0 0 -0 0</pose>
          <geometry>
            <mesh>
              <scale>1 1 1</scale>
              <uri>/home/bionicdl/catkin_ws/src/franka_ros/franka_description/models/asus_xtion.dae</uri>
            </mesh>
          </geometry>
        </visual>
        <gravity>1</gravity>
        <velocity_decay/>
        <self_collide>0</self_collide>
        <sensor name='camera' type='depth'>
          <always_on>1</always_on>
          <visualize>0</visualize>
          <update_rate>15</update_rate>
          <camera name='front'>
            <horizontal_fov>1.5</horizontal_fov>
            <image>
              <format>B8G8R8</format>
              <width>1024</width>
              <height>576</height>
            </image>
            <clip>
              <near>0.01</near>
              <far>9</far>
            </clip>
          </camera>
          <plugin name='camera_controller' filename='libgazebo_ros_openni_kinect.so'>
            <baseline>0.1</baseline>
            <alwaysOn>true</alwaysOn>
            <updateRate>15.0</updateRate>
            <cameraName>camera</cameraName>
            <imageTopicName>/camera/rgb/image_raw</imageTopicName>
            <cameraInfoTopicName>/camera/rgb/camera_info</cameraInfoTopicName>
            <depthImageTopicName>/camera/depth_registered/image_raw</depthImageTopicName>
            <depthImageCameraInfoTopicName>/camera/depth_registered/camera_info</depthImageCameraInfoTopicName>
            <pointCloudTopicName>/camera/depth_registered/points</pointCloudTopicName>
            <frameName>camera_rgb_optical_frame</frameName>
            <pointCloudCutoff>0.5</pointCloudCutoff>
            <pointCloudCutoffMax>4.5</pointCloudCutoffMax>
            <CxPrime>0</CxPrime>
            <Cx>0</Cx>
            <Cy>0</Cy>
            <focalLength>0</focalLength>
            <hackBaseline>0</hackBaseline>
            <robotNamespace>/</robotNamespace>
          </plugin>
          <pose frame=''>0 0.022 0 0 -0 0</pose>
        </sensor>
        <kinematic>0</kinematic>
      </link>
      <joint name='camera_link_joint' type='revolute'>
        <child>camera_link</child>
        <parent>world</parent>
        <axis>
          <limit>
            <lower>0</lower>
            <upper>0</upper>
          </limit>
          <dynamics>
            <damping>0</damping>
            <friction>0</friction>
            <spring_reference>0</spring_reference>
            <spring_stiffness>0</spring_stiffness>
          </dynamics>
          <use_parent_model_frame>1</use_parent_model_frame>
          <xyz>0 0 1</xyz>
        </axis>
      </joint>
      <link name='panda_link0'>
        <pose frame=''>0 0 0 0 -0 0</pose>
        <inertial>
          <pose frame=''>0 0 0 0 -0 0</pose>
          <mass>3</mass>
          <inertia>
            <ixx>0.00712225</ixx>
            <ixy>0</ixy>
            <ixz>0</ixz>
            <iyy>0.00712225</iyy>
            <iyz>0</iyz>
            <izz>0.0054</izz>
          </inertia>
        </inertial>
        <collision name='panda_link0_collision'>
          <pose frame=''>0 0 0 0 -0 0</pose>
          <geometry>
            <mesh>
              <scale>1 1 1</scale>
              <uri>/home/bionicdl/catkin_ws/src/franka_ros/franka_description/meshes/collision/link0.stl</uri>
            </mesh>
          </geometry>
          <max_contacts>10</max_contacts>
          <surface>
            <contact>
              <ode/>
            </contact>
            <bounce/>
            <friction>
              <torsional>
                <ode/>
              </torsional>
              <ode/>
            </friction>
          </surface>
        </collision>
        <visual name='panda_link0_visual'>
          <pose frame=''>0 0 0 0 -0 0</pose>
          <geometry>
            <mesh>
              <scale>1 1 1</scale>
              <uri>/home/bionicdl/catkin_ws/src/franka_ros/franka_description/meshes/visual/link0.dae</uri>
            </mesh>
          </geometry>
        </visual>
        <self_collide>0</self_collide>
        <kinematic>0</kinematic>
        <gravity>1</gravity>
      </link>
      <joint name='panda_joint_world' type='revolute'>
        <child>panda_link0</child>
        <parent>world</parent>
        <axis>
          <limit>
            <lower>0</lower>
            <upper>0</upper>
          </limit>
          <dynamics>
            <damping>0</damping>
            <friction>0</friction>
            <spring_reference>0</spring_reference>
            <spring_stiffness>0</spring_stiffness>
          </dynamics>
          <use_parent_model_frame>1</use_parent_model_frame>
          <xyz>0 0 1</xyz>
        </axis>
      </joint>
      <link name='panda_link1'>
        <pose frame=''>0 0 0.333 0 -0 0</pose>
        <inertial>
          <pose frame=''>0 0 0 0 -0 0</pose>
          <mass>3</mass>
          <inertia>
            <ixx>0.0127</ixx>
            <ixy>0</ixy>
            <ixz>0</ixz>
            <iyy>0.0127</iyy>
            <iyz>0</iyz>
            <izz>0.0054</izz>
          </inertia>
        </inertial>
        <collision name='panda_link1_collision'>
          <pose frame=''>0 0 0 0 -0 0</pose>
          <geometry>
            <mesh>
              <scale>1 1 1</scale>
              <uri>/home/bionicdl/catkin_ws/src/franka_ros/franka_description/meshes/collision/link1.stl</uri>
            </mesh>
          </geometry>
          <surface>
            <contact>
              <ode/>
            </contact>
            <friction>
              <ode/>
              <torsional>
                <ode/>
              </torsional>
            </friction>
            <bounce/>
          </surface>
          <max_contacts>10</max_contacts>
        </collision>
        <visual name='panda_link1_visual'>
          <pose frame=''>0 0 0 0 -0 0</pose>
          <geometry>
            <mesh>
              <scale>1 1 1</scale>
              <uri>/home/bionicdl/catkin_ws/src/franka_ros/franka_description/meshes/visual/link1.dae</uri>
            </mesh>
          </geometry>
          <material>
            <script>
              <uri>__default__</uri>
              <name>__default__</name>
            </script>
          </material>
        </visual>
        <gravity>0</gravity>
        <velocity_decay/>
        <self_collide>0</self_collide>
        <kinematic>0</kinematic>
      </link>
      <joint name='panda_joint1' type='revolute'>
        <child>panda_link1</child>
        <parent>panda_link0</parent>
        <axis>
          <xyz>0 0 1</xyz>
          <limit>
            <lower>-2.8973</lower>
            <upper>2.8973</upper>
            <effort>87</effort>
            <velocity>2.175</velocity>
          </limit>
          <dynamics>
            <spring_reference>0</spring_reference>
            <spring_stiffness>0</spring_stiffness>
          </dynamics>
          <use_parent_model_frame>1</use_parent_model_frame>
        </axis>
      </joint>
      <link name='panda_link2'>
        <pose frame=''>0 0 0.333 -1.5708 0 0</pose>
        <inertial>
          <pose frame=''>0 0 0 0 -0 0</pose>
          <mass>3</mass>
          <inertia>
            <ixx>0.027664</ixx>
            <ixy>0</ixy>
            <ixz>0</ixz>
            <iyy>0.027664</iyy>
            <iyz>0</iyz>
            <izz>0.0054</izz>
          </inertia>
        </inertial>
        <collision name='panda_link2_collision'>
          <pose frame=''>0 0 0 0 -0 0</pose>
          <geometry>
            <mesh>
              <scale>1 1 1</scale>
              <uri>/home/bionicdl/catkin_ws/src/franka_ros/franka_description/meshes/collision/link2.stl</uri>
            </mesh>
          </geometry>
          <surface>
            <contact>
              <ode/>
            </contact>
            <friction>
              <ode/>
              <torsional>
                <ode/>
              </torsional>
            </friction>
            <bounce/>
          </surface>
          <max_contacts>10</max_contacts>
        </collision>
        <visual name='panda_link2_visual'>
          <pose frame=''>0 0 0 0 -0 0</pose>
          <geometry>
            <mesh>
              <scale>1 1 1</scale>
              <uri>/home/bionicdl/catkin_ws/src/franka_ros/franka_description/meshes/visual/link2.dae</uri>
            </mesh>
          </geometry>
          <material>
            <script>
              <uri>__default__</uri>
              <name>__default__</name>
            </script>
          </material>
        </visual>
        <gravity>0</gravity>
        <velocity_decay/>
        <self_collide>0</self_collide>
        <kinematic>0</kinematic>
      </link>
      <joint name='panda_joint2' type='revolute'>
        <child>panda_link2</child>
        <parent>panda_link1</parent>
        <axis>
          <xyz>0 1 0</xyz>
          <limit>
            <lower>-1.7628</lower>
            <upper>1.7628</upper>
            <effort>87</effort>
            <velocity>2.175</velocity>
          </limit>
          <dynamics>
            <spring_reference>0</spring_reference>
            <spring_stiffness>0</spring_stiffness>
          </dynamics>
          <use_parent_model_frame>1</use_parent_model_frame>
        </axis>
      </joint>
      <link name='panda_link3'>
        <pose frame=''>0 -0 0.649 0 -0 0</pose>
        <inertial>
          <pose frame=''>0 0 0 0 -0 0</pose>
          <mass>2</mass>
          <inertia>
            <ixx>0.00293437</ixx>
            <ixy>0</ixy>
            <ixz>0</ixz>
            <iyy>0.00293437</iyy>
            <iyz>0</iyz>
            <izz>0.0036</izz>
          </inertia>
        </inertial>
        <collision name='panda_link3_collision'>
          <pose frame=''>0 0 0 0 -0 0</pose>
          <geometry>
            <mesh>
              <scale>1 1 1</scale>
              <uri>/home/bionicdl/catkin_ws/src/franka_ros/franka_description/meshes/collision/link3.stl</uri>
            </mesh>
          </geometry>
          <surface>
            <contact>
              <ode/>
            </contact>
            <friction>
              <ode/>
              <torsional>
                <ode/>
              </torsional>
            </friction>
            <bounce/>
          </surface>
          <max_contacts>10</max_contacts>
        </collision>
        <visual name='panda_link3_visual'>
          <pose frame=''>0 0 0 0 -0 0</pose>
          <geometry>
            <mesh>
              <scale>1 1 1</scale>
              <uri>/home/bionicdl/catkin_ws/src/franka_ros/franka_description/meshes/visual/link3.dae</uri>
            </mesh>
          </geometry>
          <material>
            <script>
              <uri>__default__</uri>
              <name>__default__</name>
            </script>
          </material>
        </visual>
        <gravity>0</gravity>
        <velocity_decay/>
        <self_collide>0</self_collide>
        <kinematic>0</kinematic>
      </link>
      <joint name='panda_joint3' type='revolute'>
        <child>panda_link3</child>
        <parent>panda_link2</parent>
        <axis>
          <xyz>0 0 1</xyz>
          <limit>
            <lower>-2.8973</lower>
            <upper>2.8973</upper>
            <effort>87</effort>
            <velocity>2.175</velocity>
          </limit>
          <dynamics>
            <spring_reference>0</spring_reference>
            <spring_stiffness>0</spring_stiffness>
          </dynamics>
          <use_parent_model_frame>1</use_parent_model_frame>
        </axis>
      </joint>
      <link name='panda_link4'>
        <pose frame=''>0.0825 -0 0.649 1.5708 -0 0</pose>
        <inertial>
          <pose frame=''>0 0 0 0 -0 0</pose>
          <mass>2</mass>
          <inertia>
            <ixx>0.00293437</ixx>
            <ixy>0</ixy>
            <ixz>0</ixz>
            <iyy>0.00293437</iyy>
            <iyz>0</iyz>
            <izz>0.0036</izz>
          </inertia>
        </inertial>
        <collision name='panda_link4_collision'>
          <pose frame=''>0 0 0 0 -0 0</pose>
          <geometry>
            <mesh>
              <scale>1 1 1</scale>
              <uri>/home/bionicdl/catkin_ws/src/franka_ros/franka_description/meshes/collision/link4.stl</uri>
            </mesh>
          </geometry>
          <surface>
            <contact>
              <ode/>
            </contact>
            <friction>
              <ode/>
              <torsional>
                <ode/>
              </torsional>
            </friction>
            <bounce/>
          </surface>
          <max_contacts>10</max_contacts>
        </collision>
        <visual name='panda_link4_visual'>
          <pose frame=''>0 0 0 0 -0 0</pose>
          <geometry>
            <mesh>
              <scale>1 1 1</scale>
              <uri>/home/bionicdl/catkin_ws/src/franka_ros/franka_description/meshes/visual/link4.dae</uri>
            </mesh>
          </geometry>
          <material>
            <script>
              <uri>__default__</uri>
              <name>__default__</name>
            </script>
          </material>
        </visual>
        <gravity>0</gravity>
        <velocity_decay/>
        <self_collide>0</self_collide>
        <kinematic>0</kinematic>
      </link>
      <joint name='panda_joint4' type='revolute'>
        <child>panda_link4</child>
        <parent>panda_link3</parent>
        <axis>
          <xyz>0 -1 0</xyz>
          <limit>
            <lower>-3.0718</lower>
            <upper>-0.0698</upper>
            <effort>87</effort>
            <velocity>2.175</velocity>
          </limit>
          <dynamics>
            <spring_reference>0</spring_reference>
            <spring_stiffness>0</spring_stiffness>
          </dynamics>
          <use_parent_model_frame>1</use_parent_model_frame>
        </axis>
      </joint>
      <link name='panda_link5'>
        <pose frame=''>-0 0 1.033 0 -0 0</pose>
        <inertial>
          <pose frame=''>0 0 0 0 -0 0</pose>
          <mass>2</mass>
          <inertia>
            <ixx>0.026376</ixx>
            <ixy>0</ixy>
            <ixz>0</ixz>
            <iyy>0.026376</iyy>
            <iyz>0</iyz>
            <izz>0.0036</izz>
          </inertia>
        </inertial>
        <collision name='panda_link5_collision'>
          <pose frame=''>0 0 0 0 -0 0</pose>
          <geometry>
            <mesh>
              <scale>1 1 1</scale>
              <uri>/home/bionicdl/catkin_ws/src/franka_ros/franka_description/meshes/collision/link5.stl</uri>
            </mesh>
          </geometry>
          <surface>
            <contact>
              <ode/>
            </contact>
            <friction>
              <ode/>
              <torsional>
                <ode/>
              </torsional>
            </friction>
            <bounce/>
          </surface>
          <max_contacts>10</max_contacts>
        </collision>
        <visual name='panda_link5_visual'>
          <pose frame=''>0 0 0 0 -0 0</pose>
          <geometry>
            <mesh>
              <scale>1 1 1</scale>
              <uri>/home/bionicdl/catkin_ws/src/franka_ros/franka_description/meshes/visual/link5.dae</uri>
            </mesh>
          </geometry>
          <material>
            <script>
              <uri>__default__</uri>
              <name>__default__</name>
            </script>
          </material>
        </visual>
        <gravity>0</gravity>
        <velocity_decay/>
        <self_collide>0</self_collide>
        <kinematic>0</kinematic>
      </link>
      <joint name='panda_joint5' type='revolute'>
        <child>panda_link5</child>
        <parent>panda_link4</parent>
        <axis>
          <xyz>0 0 1</xyz>
          <limit>
            <lower>-2.8973</lower>
            <upper>2.8973</upper>
            <effort>12</effort>
            <velocity>2.61</velocity>
          </limit>
          <dynamics>
            <spring_reference>0</spring_reference>
            <spring_stiffness>0</spring_stiffness>
          </dynamics>
          <use_parent_model_frame>1</use_parent_model_frame>
        </axis>
      </joint>
      <link name='panda_link6'>
        <pose frame=''>-0 0 1.033 1.5708 -0 0</pose>
        <inertial>
          <pose frame=''>0 0 0 0 -0 0</pose>
          <mass>2</mass>
          <inertia>
            <ixx>0.00346667</ixx>
            <ixy>0</ixy>
            <ixz>0</ixz>
            <iyy>0.00346667</iyy>
            <iyz>0</iyz>
            <izz>0.0036</izz>
          </inertia>
        </inertial>
        <collision name='panda_link6_collision'>
          <pose frame=''>0 0 0 0 -0 0</pose>
          <geometry>
            <mesh>
              <scale>1 1 1</scale>
              <uri>/home/bionicdl/catkin_ws/src/franka_ros/franka_description/meshes/collision/link6.stl</uri>
            </mesh>
          </geometry>
          <surface>
            <contact>
              <ode/>
            </contact>
            <friction>
              <ode/>
              <torsional>
                <ode/>
              </torsional>
            </friction>
            <bounce/>
          </surface>
          <max_contacts>10</max_contacts>
        </collision>
        <visual name='panda_link6_visual'>
          <pose frame=''>0 0 0 0 -0 0</pose>
          <geometry>
            <mesh>
              <scale>1 1 1</scale>
              <uri>/home/bionicdl/catkin_ws/src/franka_ros/franka_description/meshes/visual/link6.dae</uri>
            </mesh>
          </geometry>
          <material>
            <script>
              <uri>__default__</uri>
              <name>__default__</name>
            </script>
          </material>
        </visual>
        <gravity>0</gravity>
        <velocity_decay/>
        <self_collide>0</self_collide>
        <kinematic>0</kinematic>
      </link>
      <joint name='panda_joint6' type='revolute'>
        <child>panda_link6</child>
        <parent>panda_link5</parent>
        <axis>
          <xyz>0 -1 0</xyz>
          <limit>
            <lower>-0.0175</lower>
            <upper>3.7525</upper>
            <effort>12</effort>
            <velocity>2.61</velocity>
          </limit>
          <dynamics>
            <spring_reference>0</spring_reference>
            <spring_stiffness>0</spring_stiffness>
          </dynamics>
          <use_parent_model_frame>1</use_parent_model_frame>
        </axis>
      </joint>
      <link name='panda_link7'>
        <pose frame=''>0.088 0 1.033 3.14159 -0 0</pose>
        <inertial>
          <pose frame=''>0 0 0.009727 0 -0 0</pose>
          <mass>1.1</mass>
          <inertia>
            <ixx>0.00387415</ixx>
            <ixy>-0.0009</ixy>
            <ixz>0</ixz>
            <iyy>0.00387415</iyy>
            <iyz>0</iyz>
            <izz>0.002</izz>
          </inertia>
        </inertial>
        <collision name='panda_link7_collision'>
          <pose frame=''>0 0 0 0 -0 0</pose>
          <geometry>
            <mesh>
              <scale>1 1 1</scale>
              <uri>/home/bionicdl/catkin_ws/src/franka_ros/franka_description/meshes/collision/link7.stl</uri>
            </mesh>
          </geometry>
          <surface>
            <contact>
              <ode/>
            </contact>
            <friction>
              <ode/>
              <torsional>
                <ode/>
              </torsional>
            </friction>
            <bounce/>
          </surface>
          <max_contacts>10</max_contacts>
        </collision>
        <collision name='panda_link7_fixed_joint_lump__panda_hand_collision_1'>
          <pose frame=''>0 0 0.107 0 0 -0.785398</pose>
          <geometry>
            <mesh>
              <scale>1 1 1</scale>
              <uri>/home/bionicdl/catkin_ws/src/franka_ros/franka_description/meshes/collision/hand.stl</uri>
            </mesh>
          </geometry>
          <surface>
            <contact>
              <ode/>
            </contact>
            <friction>
              <ode>
                <mu>0.2</mu>
                <mu2>0.2</mu2>
              </ode>
              <torsional>
                <ode/>
              </torsional>
            </friction>
            <bounce/>
          </surface>
          <max_contacts>10</max_contacts>
        </collision>
        <visual name='panda_link7_visual'>
          <pose frame=''>0 0 0 0 -0 0</pose>
          <geometry>
            <mesh>
              <scale>1 1 1</scale>
              <uri>/home/bionicdl/catkin_ws/src/franka_ros/franka_description/meshes/visual/link7.dae</uri>
            </mesh>
          </geometry>
          <material>
            <script>
              <uri>__default__</uri>
              <name>__default__</name>
            </script>
          </material>
        </visual>
        <visual name='panda_link7_fixed_joint_lump__panda_hand_visual_1'>
          <pose frame=''>0 0 0.107 0 0 -0.785398</pose>
          <geometry>
            <mesh>
              <scale>1 1 1</scale>
              <uri>/home/bionicdl/catkin_ws/src/franka_ros/franka_description/meshes/visual/hand.dae</uri>
            </mesh>
          </geometry>
          <material>
            <script>
              <uri>__default__</uri>
              <name>__default__</name>
            </script>
          </material>
        </visual>
        <velocity_decay/>
        <gravity>0</gravity>
        <velocity_decay/>
        <self_collide>0</self_collide>
        <kinematic>0</kinematic>
      </link>
      <joint name='panda_joint7' type='revolute'>
        <child>panda_link7</child>
        <parent>panda_link6</parent>
        <axis>
          <xyz>0 0 -1</xyz>
          <limit>
            <lower>-2.8973</lower>
            <upper>2.8973</upper>
            <effort>12</effort>
            <velocity>2.61</velocity>
          </limit>
          <dynamics>
            <spring_reference>0</spring_reference>
            <spring_stiffness>0</spring_stiffness>
          </dynamics>
          <use_parent_model_frame>1</use_parent_model_frame>
        </axis>
      </joint>
      <link name='panda_leftfinger'>
        <pose frame=''>0.088 -0 0.8676 3.14159 -0 0.785398</pose>
        <inertial>
          <pose frame=''>0 0 0 0 -0 0</pose>
          <mass>0.1</mass>
          <inertia>
            <ixx>0.002</ixx>
            <ixy>0</ixy>
            <ixz>0</ixz>
            <iyy>0.0002</iyy>
            <iyz>0</iyz>
            <izz>0.0002</izz>
          </inertia>
        </inertial>
        <collision name='panda_leftfinger_collision'>
          <pose frame=''>0 0 0 0 -0 0</pose>
          <geometry>
            <mesh>
              <scale>1 1 1</scale>
              <uri>/home/bionicdl/catkin_ws/src/franka_ros/franka_description/meshes/collision/finger.stl</uri>
            </mesh>
          </geometry>
          <surface>
            <contact>
              <ode/>
            </contact>
            <friction>
              <ode/>
              <torsional>
                <ode/>
              </torsional>
            </friction>
            <bounce/>
          </surface>
          <max_contacts>10</max_contacts>
        </collision>
        <visual name='panda_leftfinger_visual'>
          <pose frame=''>0 0 0 0 -0 0</pose>
          <geometry>
            <mesh>
              <scale>1 1 1</scale>
              <uri>/home/bionicdl/catkin_ws/src/franka_ros/franka_description/meshes/visual/finger.dae</uri>
            </mesh>
          </geometry>
          <material>
            <script>
              <uri>__default__</uri>
              <name>__default__</name>
            </script>
          </material>
        </visual>
        <gravity>0</gravity>
        <velocity_decay/>
        <self_collide>0</self_collide>
        <kinematic>0</kinematic>
      </link>
      <joint name='panda_finger_joint1' type='prismatic'>
        <child>panda_leftfinger</child>
        <parent>panda_link7</parent>
        <axis>
          <xyz>0.707107 -0.707107 0</xyz>
          <limit>
            <lower>0</lower>
            <upper>0.04</upper>
            <effort>20</effort>
            <velocity>0.2</velocity>
          </limit>
          <dynamics>
            <spring_reference>0</spring_reference>
            <spring_stiffness>0</spring_stiffness>
          </dynamics>
          <use_parent_model_frame>1</use_parent_model_frame>
        </axis>
      </joint>
      <link name='panda_rightfinger'>
        <pose frame=''>0.088 -0 0.8676 3.14159 -0 0.785398</pose>
        <inertial>
          <pose frame=''>0 0 0 0 -0 0</pose>
          <mass>0.1</mass>
          <inertia>
            <ixx>0.002</ixx>
            <ixy>0</ixy>
            <ixz>0</ixz>
            <iyy>0.0002</iyy>
            <iyz>0</iyz>
            <izz>0.0002</izz>
          </inertia>
        </inertial>
        <collision name='panda_rightfinger_collision'>
          <pose frame=''>0 0 0 0 -0 -3.14159</pose>
          <geometry>
            <mesh>
              <scale>1 1 1</scale>
              <uri>/home/bionicdl/catkin_ws/src/franka_ros/franka_description/meshes/collision/finger.stl</uri>
            </mesh>
          </geometry>
          <surface>
            <contact>
              <ode>
                <kp>1e+06</kp>
                <kd>1</kd>
              </ode>
            </contact>
            <friction>
              <ode>
                <mu>30</mu>
                <mu2>30</mu2>
              </ode>
              <torsional>
                <ode/>
              </torsional>
            </friction>
            <bounce/>
          </surface>
          <max_contacts>10</max_contacts>
        </collision>
        <visual name='panda_rightfinger_visual'>
          <pose frame=''>0 0 0 0 -0 -3.14159</pose>
          <geometry>
            <mesh>
              <scale>1 1 1</scale>
              <uri>/home/bionicdl/catkin_ws/src/franka_ros/franka_description/meshes/visual/finger.dae</uri>
            </mesh>
          </geometry>
          <material>
            <script>
              <uri>__default__</uri>
              <name>__default__</name>
            </script>
          </material>
        </visual>
        <gravity>0</gravity>
        <velocity_decay/>
        <self_collide>0</self_collide>
        <kinematic>0</kinematic>
      </link>
      <joint name='panda_finger_joint2' type='prismatic'>
        <child>panda_rightfinger</child>
        <parent>panda_link7</parent>
        <axis>
          <xyz>-0.707107 0.707107 -0</xyz>
          <limit>
            <lower>0</lower>
            <upper>0.04</upper>
            <effort>20</effort>
            <velocity>0.2</velocity>
          </limit>
          <dynamics>
            <spring_reference>0</spring_reference>
            <spring_stiffness>0</spring_stiffness>
          </dynamics>
          <use_parent_model_frame>1</use_parent_model_frame>
        </axis>
      </joint>
      <plugin name='gazebo_ros_control' filename='libgazebo_ros_control.so'>
        <robotSimType>gazebo_ros_control/DefaultRobotHWSim</robotSimType>
        <robotNamespace>/</robotNamespace>
      </plugin>
      <static>0</static>
      <plugin name='gazebo_grasp_fix' filename='libgazebo_grasp_fix.so'>
        <arm>
          <arm_name>panda_arm</arm_name>
          <palm_link>panda_link7</palm_link>
          <gripper_link>panda_leftfinger</gripper_link>
          <gripper_link>panda_rightfinger</gripper_link>
        </arm>
        <forces_angle_tolerance>100</forces_angle_tolerance>
        <update_rate>4</update_rate>
        <grip_count_threshold>4</grip_count_threshold>
        <max_grip_count>8</max_grip_count>
        <release_tolerance>0.003</release_tolerance>
        <disable_collisions_on_attach>false</disable_collisions_on_attach>
        <contact_topic>__default_topic__</contact_topic>
        <robotNamespace>/</robotNamespace>
      </plugin>
      <pose frame=''>0 0 0 0 -0 0</pose>
    </model>
    <model name='dropbox'>
      <link name='link_0'>
        <pose frame=''>0 -0 0 0 0 -1.56873</pose>
        <inertial>
          <mass>1</mass>
          <inertia>
            <ixx>0.166667</ixx>
            <ixy>0</ixy>
            <ixz>0</ixz>
            <iyy>0.166667</iyy>
            <iyz>0</iyz>
            <izz>0.166667</izz>
          </inertia>
        </inertial>
        <visual name='visual'>
          <pose frame=''>0 0 0 0 -0 0</pose>
          <geometry>
            <mesh>
              <uri>model://dropbox/meshes/dropbox.dae</uri>
              <scale>1 1 1</scale>
            </mesh>
          </geometry>
          <material>
            <lighting>1</lighting>
            <script>
              <uri>file://media/materials/scripts/gazebo.material</uri>
              <name>Gazebo/Grey</name>
            </script>
            <ambient>0.3 0.3 0.3 1</ambient>
            <diffuse>0.7 0.7 0.7 1</diffuse>
            <specular>0.01 0.01 0.01 1</specular>
            <emissive>0 0 0 1</emissive>
          </material>
          <transparency>0</transparency>
          <cast_shadows>1</cast_shadows>
        </visual>
        <collision name='collision'>
          <laser_retro>0</laser_retro>
          <max_contacts>10</max_contacts>
          <pose frame=''>0 0 0 0 -0 0</pose>
          <geometry>
            <mesh>
              <uri>model://dropbox/meshes/dropbox.dae</uri>
              <scale>1 1 1</scale>
            </mesh>
          </geometry>
          <surface>
            <friction>
              <ode>
                <mu>1</mu>
                <mu2>1</mu2>
                <fdir1>0 0 0</fdir1>
                <slip1>0</slip1>
                <slip2>0</slip2>
              </ode>
              <torsional>
                <coefficient>1</coefficient>
                <patch_radius>0</patch_radius>
                <surface_radius>0</surface_radius>
                <use_patch_radius>1</use_patch_radius>
                <ode>
                  <slip>0</slip>
                </ode>
              </torsional>
            </friction>
            <bounce>
              <restitution_coefficient>0</restitution_coefficient>
              <threshold>1e+06</threshold>
            </bounce>
            <contact>
              <collide_without_contact>0</collide_without_contact>
              <collide_without_contact_bitmask>1</collide_without_contact_bitmask>
              <collide_bitmask>1</collide_bitmask>
              <ode>
                <soft_cfm>0</soft_cfm>
                <soft_erp>0.2</soft_erp>
                <kp>1e+13</kp>
                <kd>1</kd>
                <max_vel>0.01</max_vel>
                <min_depth>0</min_depth>
              </ode>
              <bullet>
                <split_impulse>1</split_impulse>
                <split_impulse_penetration_threshold>-0.01</split_impulse_penetration_threshold>
                <soft_cfm>0</soft_cfm>
                <soft_erp>0.2</soft_erp>
                <kp>1e+13</kp>
                <kd>1</kd>
              </bullet>
            </contact>
          </surface>
        </collision>
        <self_collide>0</self_collide>
        <kinematic>0</kinematic>
        <gravity>1</gravity>
      </link>
      <static>1</static>
      <allow_auto_disable>1</allow_auto_disable>
      <pose frame=''>-0.002951 -0.729748 0 0 -0 0</pose>
    </model>
    <model name='biscuits'>
      <link name='biscuits_link'>
        <inertial>
          <pose frame=''>0 0 0 0 -0 0</pose>
          <mass>0.1</mass>
          <inertia>
            <ixx>1</ixx>
            <ixy>0</ixy>
            <ixz>0</ixz>
            <iyy>1</iyy>
            <iyz>0</iyz>
            <izz>1</izz>
          </inertia>
        </inertial>
        <visual name='biscuits_visual'>
          <pose frame=''>0 0 0 0 -0 0</pose>
          <material>
            <script>
              <uri>model://biscuits/materials/scripts</uri>
              <uri>model://biscuits/materials/textures</uri>
              <name>biscuits</name>
            </script>
          </material>
          <geometry>
            <mesh>
              <uri>model://biscuits/meshes/biscuits.dae</uri>
              <scale>1 1 1</scale>
            </mesh>
          </geometry>
        </visual>
        <collision name='biscuits_collision'>
          <pose frame=''>0.015 0.01 0.075 0 -0 2.2</pose>
          <geometry>
            <box>
              <size>0.19 0.06 0.15</size>
            </box>
          </geometry>
          <max_contacts>10</max_contacts>
          <surface>
            <contact>
              <ode/>
            </contact>
            <bounce/>
            <friction>
              <torsional>
                <ode/>
              </torsional>
              <ode/>
            </friction>
          </surface>
        </collision>
        <self_collide>0</self_collide>
        <kinematic>0</kinematic>
        <gravity>1</gravity>
      </link>
      <pose frame=''>0.671337 -0.215875 0 0 -0 0</pose>
    </model>
    <model name='soap'>
      <link name='soap_link'>
        <inertial>
          <pose frame=''>0 0 0 0 -0 0</pose>
          <mass>0.08</mass>
          <inertia>
            <ixx>1</ixx>
            <ixy>0</ixy>
            <ixz>0</ixz>
            <iyy>1</iyy>
            <iyz>0</iyz>
            <izz>1</izz>
          </inertia>
        </inertial>
        <visual name='soap_visual'>
          <pose frame=''>0 0 0 0 -0 0</pose>
          <material>
            <script>
              <uri>model://soap/materials/scripts</uri>
              <uri>model://soap/materials/textures</uri>
              <name>soap</name>
            </script>
          </material>
          <geometry>
            <mesh>
              <uri>model://soap/meshes/soap.dae</uri>
              <scale>1 1 1</scale>
            </mesh>
          </geometry>
        </visual>
        <collision name='soap_collision'>
          <pose frame=''>0.02 0.002 0.05 0 0 -1.05</pose>
          <geometry>
            <box>
              <size>0.14 0.065 0.1</size>
            </box>
          </geometry>
          <max_contacts>10</max_contacts>
          <surface>
            <contact>
              <ode/>
            </contact>
            <bounce/>
            <friction>
              <torsional>
                <ode/>
              </torsional>
              <ode/>
            </friction>
          </surface>
        </collision>
        <self_collide>0</self_collide>
        <kinematic>0</kinematic>
        <gravity>1</gravity>
      </link>
      <pose frame=''>0.422786 -0.00359 0 0 -0 0</pose>
    </model>
    <model name='snacks_0'>
      <link name='snacks_link'>
        <inertial>
          <pose frame=''>0 0 0 0 -0 0</pose>
          <mass>0.08</mass>
          <inertia>
            <ixx>1</ixx>
            <ixy>0</ixy>
            <ixz>0</ixz>
            <iyy>1</iyy>
            <iyz>0</iyz>
            <izz>1</izz>
          </inertia>
        </inertial>
        <visual name='snacks_visual'>
          <pose frame=''>0 0 0 0 -0 0</pose>
          <material>
            <script>
              <uri>model://snacks/materials/scripts</uri>
              <uri>model://snacks/materials/textures</uri>
              <name>snacks</name>
            </script>
          </material>
          <geometry>
            <mesh>
              <uri>model://snacks/meshes/snacks.dae</uri>
              <scale>1 1 1</scale>
            </mesh>
          </geometry>
        </visual>
        <collision name='snacks_collision'>
          <pose frame=''>0.04 0.02 0.117 0 -0 2.1</pose>
          <geometry>
            <box>
              <size>0.165 0.06 0.235</size>
            </box>
          </geometry>
          <max_contacts>10</max_contacts>
          <surface>
            <contact>
              <ode/>
            </contact>
            <bounce/>
            <friction>
              <torsional>
                <ode/>
              </torsional>
              <ode/>
            </friction>
          </surface>
        </collision>
        <self_collide>0</self_collide>
        <kinematic>0</kinematic>
        <gravity>1</gravity>
      </link>
      <pose frame=''>0.771519 0.064942 0 0 -0 0</pose>
    </model>
    <state world_name='default'>
      <sim_time>493 871000000</sim_time>
      <real_time>506 493675185</real_time>
      <wall_time>1543826404 791456064</wall_time>
      <iterations>493871</iterations>
      <model name='biscuits'>
        <pose frame=''>0.671337 -0.215875 0 1e-06 -1e-06 0</pose>
        <scale>1 1 1</scale>
        <link name='biscuits_link'>
          <pose frame=''>0.671337 -0.215875 0 1e-06 -1e-06 0</pose>
          <velocity>0 0 0 0 -0 0</velocity>
          <acceleration>0 0 -0.00884 0.067708 0.063802 0</acceleration>
          <wrench>0 0 -0.000884 0 -0 0</wrench>
        </link>
      </model>
      <model name='dropbox'>
        <pose frame=''>-0.2 -0.70 0 0 -0 0</pose>
        <scale>1 1 1</scale>
        <link name='link_0'>
          <pose frame=''>-0.2 -0.70 0 0 0 -1.56873</pose>
          <velocity>0 0 0 0 -0 0</velocity>
          <acceleration>0 0 0 0 -0 0</acceleration>
          <wrench>0 0 0 0 -0 0</wrench>
        </link>
      </model>
      <model name='ground_plane'>
        <pose frame=''>0 0 0 0 -0 0</pose>
        <scale>1 1 1</scale>
        <link name='link'>
          <pose frame=''>0 0 0 0 -0 0</pose>
          <velocity>0 0 0 0 -0 0</velocity>
          <acceleration>0 0 0 0 -0 0</acceleration>
          <wrench>0 0 0 0 -0 0</wrench>
        </link>
      </model>
      <model name='robot'>
        <pose frame=''>0 0 0 0 -0 0</pose>
        <scale>1 1 1</scale>
        <link name='camera_link'>
          <pose frame=''>0.6 0 0.8 0 1.57 0</pose>
          <velocity>0 0 0 0 -0 0</velocity>
          <acceleration>0 0 0 0 -0 0</acceleration>
          <wrench>0 0 0 0 -0 0</wrench>
        </link>
        <link name='panda_leftfinger'>
          <pose frame=''>-0.139979 -0.66657 0.357013 -3.14135 -0.002976 -1.76164</pose>
          <velocity>6.9e-05 0.000886 -0.000265 0.002542 -0.000952 -0.000461</velocity>
          <acceleration>0.069088 0.886002 -0.265387 0.197012 1.4393 -0.449068</acceleration>
          <wrench>0.006909 0.0886 -0.026539 0 -0 0</wrench>
        </link>
        <link name='panda_link0'>
          <pose frame=''>0 0 2e-05 -0.000144 9e-06 -9e-06</pose>
          <velocity>5e-06 1e-06 0.004052 -0.031831 0.002651 -8e-06</velocity>
          <acceleration>0.011476 0.000392 8.10166 -0.847959 0.15736 0.258083</acceleration>
          <wrench>0.034429 0.001175 24.305 0 -0 0</wrench>
        </link>
        <link name='panda_link1'>
          <pose frame=''>2e-06 2.8e-05 0.33302 3e-06 -5.4e-05 -1.71927</pose>
          <velocity>0.000187 0.00426 0.004064 -0.001817 -0.001329 0.006702</velocity>
          <acceleration>0.186922 4.25977 4.06372 -1.81673 -1.32906 0.418726</acceleration>
          <wrench>0.560766 12.7793 12.1912 0 -0 0</wrench>
        </link>
        <link name='panda_link2'>
          <pose frame=''>2e-06 2.7e-05 0.33302 -1.5708 0.426097 -1.71926</pose>
          <velocity>0.000177 0.004151 0.004077 -0.000358 -0.001726 0.004678</velocity>
          <acceleration>0.176862 4.15123 4.07665 2.38095 -1.47545 -2.2285</acceleration>
          <wrench>0.530587 12.4537 12.2299 0 -0 0</wrench>
        </link>
        <link name='panda_link3'>
          <pose frame=''>-0.019319 -0.129152 0.620761 4.1e-05 0.426126 -1.71917</pose>
          <velocity>5.8e-05 0.000101 0.001901 0.014191 -0.004454 0.004565</velocity>
          <acceleration>0.058359 0.101124 1.90101 -1.44823 0.854926 1.4395</acceleration>
          <wrench>0.116717 0.202247 3.80202 0 -0 0</wrench>
        </link>
        <link name='panda_link4'>
          <pose frame=''>-0.030424 -0.20345 0.586661 -1.5709 1.1942 1.42231</pose>
          <velocity>0.000434 0.000355 0.001129 0.006822 -0.002801 0.002678</velocity>
          <acceleration>0.43434 0.35479 1.129 2.37114 -0.53609 0.144404</acceleration>
          <wrench>0.868681 0.70958 2.258 0 -0 0</wrench>
        </link>
        <link name='panda_link5'>
          <pose frame=''>-0.0877 -0.586623 0.52216 3.14127 1.1942 1.42209</pose>
          <velocity>-0.000431 0.000609 5e-05 0.002955 -0.001141 -0.000358</velocity>
          <acceleration>-0.430824 0.608792 0.049513 2.38034 1.29729 -1.58643</acceleration>
          <wrench>-0.861648 1.21758 0.099027 0 -0 0</wrench>
        </link>
        <link name='panda_link6'>
          <pose frame=''>-0.0877 -0.586624 0.52216 1.57092 -0.002977 -1.71921</pose>
          <velocity>-0.000449 0.000541 5.4e-05 0.003038 -0.001126 -0.000343</velocity>
          <acceleration>-0.44929 0.540637 0.053982 2.92203 -1.10848 -0.355838</acceleration>
          <wrench>-0.89858 1.08127 0.107965 0 -0 0</wrench>
        </link>
        <link name='panda_link7'>
          <pose frame=''>-0.100712 -0.673656 0.522422 -3.13932 -0.001928 -2.54704</pose>
          <velocity>-0.000513 0.0005 -0.000241 0.003184 -0.001126 -0.000587</velocity>
          <acceleration>-0.501895 0.531346 -0.240839 1.3501 -1.21266 2.55092</acceleration>
          <wrench>-0.552084 0.584481 -0.264923 0 -0 0</wrench>
        </link>
        <link name='panda_rightfinger'>
          <pose frame=''>-0.061574 -0.681718 0.357033 -3.14135 -0.002976 -1.76164</pose>
          <velocity>6.3e-05 0.000855 -0.000227 0.002642 -0.000967 -0.000773</velocity>
          <acceleration>0.062763 0.855472 -0.227326 1.17081 1.2667 -0.760406</acceleration>
          <wrench>0.006276 0.085547 -0.022733 0 -0 0</wrench>
        </link>
      </model>
      <model name='snacks_0'>
        <pose frame=''>0.771517 0.064941 0.000416 0.002915 -0.004974 -7e-06</pose>
        <scale>1 1 1</scale>
        <link name='snacks_link'>
          <pose frame=''>0.771517 0.064941 0.000416 0.002915 -0.004974 -7e-06</pose>
          <velocity>0 0 0 0 -0 0</velocity>
          <acceleration>-1.7e-05 2.3e-05 -0.005886 -0.051994 -0.043686 0</acceleration>
          <wrench>-1e-06 2e-06 -0.000471 0 -0 0</wrench>
        </link>
      </model>
      <model name='soap'>
        <pose frame=''>0.422786 -0.00359 0 0 0 -0.7</pose>
        <scale>1 1 1</scale>
        <link name='soap_link'>
          <pose frame=''>0.422786 -0.00359 0 0 0 -0.7</pose>
          <velocity>0 0 0 0 -0 0</velocity>
          <acceleration>0 0 -0.003149 0.049625 0.002286 0</acceleration>
          <wrench>0 0 -0.000252 0 -0 0</wrench>
        </link>
      </model>
      <light name='sun'>
        <pose frame=''>0 0 10 0 -0 0</pose>
      </light>
    </state>
    <gui fullscreen='0'>
      <camera name='user_camera'>
        <pose frame=''>0.009302 0.002843 3.74616 0 1.56675 -3.14159</pose>
        <view_controller>orbit</view_controller>
        <projection_type>perspective</projection_type>
      </camera>
    </gui>
  </world>
</sdf>
