<sdf version='1.6'>
  <world name='default'>
    <light name='sun' type='directional'>
      <cast_shadows>1</cast_shadows>
      <pose frame=''>0 0 10 0 -0 0</pose>
      <diffuse>0.8 0.8 0.8 1</diffuse>
      <specular>0.1 0.1 0.1 1</specular>
      <attenuation>
        <range>1000</range>
        <constant>0.9</constant>
        <linear>0.01</linear>
        <quadratic>0.001</quadratic>
      </attenuation>
      <direction>-0.5 0.5 -1</direction>
    </light>
    <model name='ground_plane'>
      <static>1</static>
      <link name='link'>
        <collision name='collision'>
          <geometry>
            <plane>
              <normal>0 0 1</normal>
              <size>100 100</size>
            </plane>
          </geometry>
          <surface>
            <friction>
              <ode>
                <mu>100</mu>
                <mu2>50</mu2>
              </ode>
              <torsional>
                <ode/>
              </torsional>
            </friction>
            <contact>
              <ode/>
            </contact>
            <bounce/>
          </surface>
          <max_contacts>10</max_contacts>
        </collision>
        <visual name='visual'>
          <cast_shadows>0</cast_shadows>
          <geometry>
            <plane>
              <normal>0 0 1</normal>
              <size>100 100</size>
            </plane>
          </geometry>
          <material>
            <script>
              <uri>file://media/materials/scripts/gazebo.material</uri>
              <name>Gazebo/Grey</name>
            </script>
          </material>
        </visual>
        <self_collide>0</self_collide>
        <kinematic>0</kinematic>
        <gravity>1</gravity>
      </link>
    </model>
    <gravity>0 0 -9.8</gravity>
    <magnetic_field>6e-06 2.3e-05 -4.2e-05</magnetic_field>
    <atmosphere type='adiabatic'/>
    <physics name='default_physics' default='0' type='ode'>
      <max_step_size>0.001</max_step_size>
      <real_time_factor>1</real_time_factor>
      <real_time_update_rate>1000</real_time_update_rate>
    </physics>
    <scene>
      <ambient>0.4 0.4 0.4 1</ambient>
      <background>0.7 0.7 0.7 1</background>
      <shadows>1</shadows>
    </scene>
    <spherical_coordinates>
      <surface_model>EARTH_WGS84</surface_model>
      <latitude_deg>0</latitude_deg>
      <longitude_deg>0</longitude_deg>
      <elevation>0</elevation>
      <heading_deg>0</heading_deg>
    </spherical_coordinates>
    <model name='robot'>
      <link name='camera_link'>
        <pose frame=''>0.6 0 0.8 0 1.57 0</pose>
        <inertial>
          <pose frame=''>0 0 0 0 -0 0</pose>
          <mass>0.2</mass>
          <inertia>
            <ixx>0.00058083</ixx>
            <ixy>0</ixy>
            <ixz>0</ixz>
            <iyy>3.0833e-05</iyy>
            <iyz>0</iyz>
            <izz>0.00059083</izz>
          </inertia>
        </inertial>
        <collision name='camera_link_collision'>
          <pose frame=''>-0.016 0 0 0 -0 0</pose>
          <geometry>
            <box>
              <size>0.036 0.18 0.04</size>
            </box>
          </geometry>
          <max_contacts>10</max_contacts>
          <surface>
            <contact>
              <ode/>
            </contact>
            <bounce/>
            <friction>
              <torsional>
                <ode/>
              </torsional>
              <ode/>
            </friction>
          </surface>
        </collision>
        <visual name='camera_link_visual'>
          <pose frame=''>0 0 0 0 -0 0</pose>
          <geometry>
            <mesh>
              <scale>1 1 1</scale>
              <uri>/home/bionicdl/catkin_ws/src/franka_ros/franka_description/models/asus_xtion.dae</uri>
            </mesh>
          </geometry>
        </visual>
        <gravity>1</gravity>
        <velocity_decay/>
        <self_collide>0</self_collide>
        <sensor name='camera' type='depth'>
          <always_on>1</always_on>
          <visualize>0</visualize>
          <update_rate>15</update_rate>
          <camera name='front'>
            <horizontal_fov>1.5</horizontal_fov>
            <image>
              <format>B8G8R8</format>
              <width>1024</width>
              <height>576</height>
            </image>
            <clip>
              <near>0.01</near>
              <far>9</far>
            </clip>
          </camera>
          <plugin name='camera_controller' filename='libgazebo_ros_openni_kinect.so'>
            <baseline>0.1</baseline>
            <alwaysOn>true</alwaysOn>
            <updateRate>15.0</updateRate>
            <cameraName>camera</cameraName>
            <imageTopicName>/camera/rgb/image_raw</imageTopicName>
            <cameraInfoTopicName>/camera/rgb/camera_info</cameraInfoTopicName>
            <depthImageTopicName>/camera/depth_registered/image_raw</depthImageTopicName>
            <depthImageCameraInfoTopicName>/camera/depth_registered/camera_info</depthImageCameraInfoTopicName>
            <pointCloudTopicName>/camera/depth_registered/points</pointCloudTopicName>
            <frameName>camera_rgb_optical_frame</frameName>
            <pointCloudCutoff>0.5</pointCloudCutoff>
            <pointCloudCutoffMax>4.5</pointCloudCutoffMax>
            <CxPrime>0</CxPrime>
            <Cx>0</Cx>
            <Cy>0</Cy>
            <focalLength>0</focalLength>
            <hackBaseline>0</hackBaseline>
            <robotNamespace>/</robotNamespace>
          </plugin>
          <pose frame=''>0 0.022 0 0 -0 0</pose>
        </sensor>
        <kinematic>0</kinematic>
      </link>
      <joint name='camera_link_joint' type='revolute'>
        <child>camera_link</child>
        <parent>world</parent>
        <axis>
          <limit>
            <lower>0</lower>
            <upper>0</upper>
          </limit>
          <dynamics>
            <damping>0</damping>
            <friction>0</friction>
            <spring_reference>0</spring_reference>
            <spring_stiffness>0</spring_stiffness>
          </dynamics>
          <use_parent_model_frame>1</use_parent_model_frame>
          <xyz>0 0 1</xyz>
        </axis>
      </joint>
      <link name='panda_link0'>
        <pose frame=''>0 0 0 0 -0 0</pose>
        <inertial>
          <pose frame=''>0 0 0 0 -0 0</pose>
          <mass>3</mass>
          <inertia>
            <ixx>0.00712225</ixx>
            <ixy>0</ixy>
            <ixz>0</ixz>
            <iyy>0.00712225</iyy>
            <iyz>0</iyz>
            <izz>0.0054</izz>
          </inertia>
        </inertial>
        <collision name='panda_link0_collision'>
          <pose frame=''>0 0 0 0 -0 0</pose>
          <geometry>
            <mesh>
              <scale>1 1 1</scale>
              <uri>/home/bionicdl/catkin_ws/src/franka_ros/franka_description/meshes/collision/link0.stl</uri>
            </mesh>
          </geometry>
          <max_contacts>10</max_contacts>
          <surface>
            <contact>
              <ode/>
            </contact>
            <bounce/>
            <friction>
              <torsional>
                <ode/>
              </torsional>
              <ode/>
            </friction>
          </surface>
        </collision>
        <visual name='panda_link0_visual'>
          <pose frame=''>0 0 0 0 -0 0</pose>
          <geometry>
            <mesh>
              <scale>1 1 1</scale>
              <uri>/home/bionicdl/catkin_ws/src/franka_ros/franka_description/meshes/visual/link0.dae</uri>
            </mesh>
          </geometry>
        </visual>
        <self_collide>0</self_collide>
        <kinematic>0</kinematic>
        <gravity>1</gravity>
      </link>
      <joint name='panda_joint_world' type='revolute'>
        <child>panda_link0</child>
        <parent>world</parent>
        <axis>
          <limit>
            <lower>0</lower>
            <upper>0</upper>
          </limit>
          <dynamics>
            <damping>0</damping>
            <friction>0</friction>
            <spring_reference>0</spring_reference>
            <spring_stiffness>0</spring_stiffness>
          </dynamics>
          <use_parent_model_frame>1</use_parent_model_frame>
          <xyz>0 0 1</xyz>
        </axis>
      </joint>
      <link name='panda_link1'>
        <pose frame=''>0 0 0.333 0 -0 0</pose>
        <inertial>
          <pose frame=''>0 0 0 0 -0 0</pose>
          <mass>3</mass>
          <inertia>
            <ixx>0.0127</ixx>
            <ixy>0</ixy>
            <ixz>0</ixz>
            <iyy>0.0127</iyy>
            <iyz>0</iyz>
            <izz>0.0054</izz>
          </inertia>
        </inertial>
        <collision name='panda_link1_collision'>
          <pose frame=''>0 0 0 0 -0 0</pose>
          <geometry>
            <mesh>
              <scale>1 1 1</scale>
              <uri>/home/bionicdl/catkin_ws/src/franka_ros/franka_description/meshes/collision/link1.stl</uri>
            </mesh>
          </geometry>
          <surface>
            <contact>
              <ode/>
            </contact>
            <friction>
              <ode/>
              <torsional>
                <ode/>
              </torsional>
            </friction>
            <bounce/>
          </surface>
          <max_contacts>10</max_contacts>
        </collision>
        <visual name='panda_link1_visual'>
          <pose frame=''>0 0 0 0 -0 0</pose>
          <geometry>
            <mesh>
              <scale>1 1 1</scale>
              <uri>/home/bionicdl/catkin_ws/src/franka_ros/franka_description/meshes/visual/link1.dae</uri>
            </mesh>
          </geometry>
          <material>
            <script>
              <uri>__default__</uri>
              <name>__default__</name>
            </script>
          </material>
        </visual>
        <gravity>0</gravity>
        <velocity_decay/>
        <self_collide>0</self_collide>
        <kinematic>0</kinematic>
      </link>
      <joint name='panda_joint1' type='revolute'>
        <child>panda_link1</child>
        <parent>panda_link0</parent>
        <axis>
          <xyz>0 0 1</xyz>
          <limit>
            <lower>-2.8973</lower>
            <upper>2.8973</upper>
            <effort>87</effort>
            <velocity>2.175</velocity>
          </limit>
          <dynamics>
            <spring_reference>0</spring_reference>
            <spring_stiffness>0</spring_stiffness>
          </dynamics>
          <use_parent_model_frame>1</use_parent_model_frame>
        </axis>
      </joint>
      <link name='panda_link2'>
        <pose frame=''>0 0 0.333 -1.5708 0 0</pose>
        <inertial>
          <pose frame=''>0 0 0 0 -0 0</pose>
          <mass>3</mass>
          <inertia>
            <ixx>0.027664</ixx>
            <ixy>0</ixy>
            <ixz>0</ixz>
            <iyy>0.027664</iyy>
            <iyz>0</iyz>
            <izz>0.0054</izz>
          </inertia>
        </inertial>
        <collision name='panda_link2_collision'>
          <pose frame=''>0 0 0 0 -0 0</pose>
          <geometry>
            <mesh>
              <scale>1 1 1</scale>
              <uri>/home/bionicdl/catkin_ws/src/franka_ros/franka_description/meshes/collision/link2.stl</uri>
            </mesh>
          </geometry>
          <surface>
            <contact>
              <ode/>
            </contact>
            <friction>
              <ode/>
              <torsional>
                <ode/>
              </torsional>
            </friction>
            <bounce/>
          </surface>
          <max_contacts>10</max_contacts>
        </collision>
        <visual name='panda_link2_visual'>
          <pose frame=''>0 0 0 0 -0 0</pose>
          <geometry>
            <mesh>
              <scale>1 1 1</scale>
              <uri>/home/bionicdl/catkin_ws/src/franka_ros/franka_description/meshes/visual/link2.dae</uri>
            </mesh>
          </geometry>
          <material>
            <script>
              <uri>__default__</uri>
              <name>__default__</name>
            </script>
          </material>
        </visual>
        <gravity>0</gravity>
        <velocity_decay/>
        <self_collide>0</self_collide>
        <kinematic>0</kinematic>
      </link>
      <joint name='panda_joint2' type='revolute'>
        <child>panda_link2</child>
        <parent>panda_link1</parent>
        <axis>
          <xyz>0 1 0</xyz>
          <limit>
            <lower>-1.7628</lower>
            <upper>1.7628</upper>
            <effort>87</effort>
            <velocity>2.175</velocity>
          </limit>
          <dynamics>
            <spring_reference>0</spring_reference>
            <spring_stiffness>0</spring_stiffness>
          </dynamics>
          <use_parent_model_frame>1</use_parent_model_frame>
        </axis>
      </joint>
      <link name='panda_link3'>
        <pose frame=''>0 -0 0.649 0 -0 0</pose>
        <inertial>
          <pose frame=''>0 0 0 0 -0 0</pose>
          <mass>2</mass>
          <inertia>
            <ixx>0.00293437</ixx>
            <ixy>0</ixy>
            <ixz>0</ixz>
            <iyy>0.00293437</iyy>
            <iyz>0</iyz>
            <izz>0.0036</izz>
          </inertia>
        </inertial>
        <collision name='panda_link3_collision'>
          <pose frame=''>0 0 0 0 -0 0</pose>
          <geometry>
            <mesh>
              <scale>1 1 1</scale>
              <uri>/home/bionicdl/catkin_ws/src/franka_ros/franka_description/meshes/collision/link3.stl</uri>
            </mesh>
          </geometry>
          <surface>
            <contact>
              <ode/>
            </contact>
            <friction>
              <ode/>
              <torsional>
                <ode/>
              </torsional>
            </friction>
            <bounce/>
          </surface>
          <max_contacts>10</max_contacts>
        </collision>
        <visual name='panda_link3_visual'>
          <pose frame=''>0 0 0 0 -0 0</pose>
          <geometry>
            <mesh>
              <scale>1 1 1</scale>
              <uri>/home/bionicdl/catkin_ws/src/franka_ros/franka_description/meshes/visual/link3.dae</uri>
            </mesh>
          </geometry>
          <material>
            <script>
              <uri>__default__</uri>
              <name>__default__</name>
            </script>
          </material>
        </visual>
        <gravity>0</gravity>
        <velocity_decay/>
        <self_collide>0</self_collide>
        <kinematic>0</kinematic>
      </link>
      <joint name='panda_joint3' type='revolute'>
        <child>panda_link3</child>
        <parent>panda_link2</parent>
        <axis>
          <xyz>0 0 1</xyz>
          <limit>
            <lower>-2.8973</lower>
            <upper>2.8973</upper>
            <effort>87</effort>
            <velocity>2.175</velocity>
          </limit>
          <dynamics>
            <spring_reference>0</spring_reference>
            <spring_stiffness>0</spring_stiffness>
          </dynamics>
          <use_parent_model_frame>1</use_parent_model_frame>
        </axis>
      </joint>
      <link name='panda_link4'>
        <pose frame=''>0.0825 -0 0.649 1.5708 -0 0</pose>
        <inertial>
          <pose frame=''>0 0 0 0 -0 0</pose>
          <mass>2</mass>
          <inertia>
            <ixx>0.00293437</ixx>
            <ixy>0</ixy>
            <ixz>0</ixz>
            <iyy>0.00293437</iyy>
            <iyz>0</iyz>
            <izz>0.0036</izz>
          </inertia>
        </inertial>
        <collision name='panda_link4_collision'>
          <pose frame=''>0 0 0 0 -0 0</pose>
          <geometry>
            <mesh>
              <scale>1 1 1</scale>
              <uri>/home/bionicdl/catkin_ws/src/franka_ros/franka_description/meshes/collision/link4.stl</uri>
            </mesh>
          </geometry>
          <surface>
            <contact>
              <ode/>
            </contact>
            <friction>
              <ode/>
              <torsional>
                <ode/>
              </torsional>
            </friction>
            <bounce/>
          </surface>
          <max_contacts>10</max_contacts>
        </collision>
        <visual name='panda_link4_visual'>
          <pose frame=''>0 0 0 0 -0 0</pose>
          <geometry>
            <mesh>
              <scale>1 1 1</scale>
              <uri>/home/bionicdl/catkin_ws/src/franka_ros/franka_description/meshes/visual/link4.dae</uri>
            </mesh>
          </geometry>
          <material>
            <script>
              <uri>__default__</uri>
              <name>__default__</name>
            </script>
          </material>
        </visual>
        <gravity>0</gravity>
        <velocity_decay/>
        <self_collide>0</self_collide>
        <kinematic>0</kinematic>
      </link>
      <joint name='panda_joint4' type='revolute'>
        <child>panda_link4</child>
        <parent>panda_link3</parent>
        <axis>
          <xyz>0 -1 0</xyz>
          <limit>
            <lower>-3.0718</lower>
            <upper>-0.0698</upper>
            <effort>87</effort>
            <velocity>2.175</velocity>
          </limit>
          <dynamics>
            <spring_reference>0</spring_reference>
            <spring_stiffness>0</spring_stiffness>
          </dynamics>
          <use_parent_model_frame>1</use_parent_model_frame>
        </axis>
      </joint>
      <link name='panda_link5'>
        <pose frame=''>-0 0 1.033 0 -0 0</pose>
        <inertial>
          <pose frame=''>0 0 0 0 -0 0</pose>
          <mass>2</mass>
          <inertia>
            <ixx>0.026376</ixx>
            <ixy>0</ixy>
            <ixz>0</ixz>
            <iyy>0.026376</iyy>
            <iyz>0</iyz>
            <izz>0.0036</izz>
          </inertia>
        </inertial>
        <collision name='panda_link5_collision'>
          <pose frame=''>0 0 0 0 -0 0</pose>
          <geometry>
            <mesh>
              <scale>1 1 1</scale>
              <uri>/home/bionicdl/catkin_ws/src/franka_ros/franka_description/meshes/collision/link5.stl</uri>
            </mesh>
          </geometry>
          <surface>
            <contact>
              <ode/>
            </contact>
            <friction>
              <ode/>
              <torsional>
                <ode/>
              </torsional>
            </friction>
            <bounce/>
          </surface>
          <max_contacts>10</max_contacts>
        </collision>
        <visual name='panda_link5_visual'>
          <pose frame=''>0 0 0 0 -0 0</pose>
          <geometry>
            <mesh>
              <scale>1 1 1</scale>
              <uri>/home/bionicdl/catkin_ws/src/franka_ros/franka_description/meshes/visual/link5.dae</uri>
            </mesh>
          </geometry>
          <material>
            <script>
              <uri>__default__</uri>
              <name>__default__</name>
            </script>
          </material>
        </visual>
        <gravity>0</gravity>
        <velocity_decay/>
        <self_collide>0</self_collide>
        <kinematic>0</kinematic>
      </link>
      <joint name='panda_joint5' type='revolute'>
        <child>panda_link5</child>
        <parent>panda_link4</parent>
        <axis>
          <xyz>0 0 1</xyz>
          <limit>
            <lower>-2.8973</lower>
            <upper>2.8973</upper>
            <effort>12</effort>
            <velocity>2.61</velocity>
          </limit>
          <dynamics>
            <spring_reference>0</spring_reference>
            <spring_stiffness>0</spring_stiffness>
          </dynamics>
          <use_parent_model_frame>1</use_parent_model_frame>
        </axis>
      </joint>
      <link name='panda_link6'>
        <pose frame=''>-0 0 1.033 1.5708 -0 0</pose>
        <inertial>
          <pose frame=''>0 0 0 0 -0 0</pose>
          <mass>2</mass>
          <inertia>
            <ixx>0.00346667</ixx>
            <ixy>0</ixy>
            <ixz>0</ixz>
            <iyy>0.00346667</iyy>
            <iyz>0</iyz>
            <izz>0.0036</izz>
          </inertia>
        </inertial>
        <collision name='panda_link6_collision'>
          <pose frame=''>0 0 0 0 -0 0</pose>
          <geometry>
            <mesh>
              <scale>1 1 1</scale>
              <uri>/home/bionicdl/catkin_ws/src/franka_ros/franka_description/meshes/collision/link6.stl</uri>
            </mesh>
          </geometry>
          <surface>
            <contact>
              <ode/>
            </contact>
            <friction>
              <ode/>
              <torsional>
                <ode/>
              </torsional>
            </friction>
            <bounce/>
          </surface>
          <max_contacts>10</max_contacts>
        </collision>
        <visual name='panda_link6_visual'>
          <pose frame=''>0 0 0 0 -0 0</pose>
          <geometry>
            <mesh>
              <scale>1 1 1</scale>
              <uri>/home/bionicdl/catkin_ws/src/franka_ros/franka_description/meshes/visual/link6.dae</uri>
            </mesh>
          </geometry>
          <material>
            <script>
              <uri>__default__</uri>
              <name>__default__</name>
            </script>
          </material>
        </visual>
        <gravity>0</gravity>
        <velocity_decay/>
        <self_collide>0</self_collide>
        <kinematic>0</kinematic>
      </link>
      <joint name='panda_joint6' type='revolute'>
        <child>panda_link6</child>
        <parent>panda_link5</parent>
        <axis>
          <xyz>0 -1 0</xyz>
          <limit>
            <lower>-0.0175</lower>
            <upper>3.7525</upper>
            <effort>12</effort>
            <velocity>2.61</velocity>
          </limit>
          <dynamics>
            <spring_reference>0</spring_reference>
            <spring_stiffness>0</spring_stiffness>
          </dynamics>
          <use_parent_model_frame>1</use_parent_model_frame>
        </axis>
      </joint>
      <link name='panda_link7'>
        <pose frame=''>0.088 0 1.033 3.14159 -0 0</pose>
        <inertial>
          <pose frame=''>0 0 0.009727 0 -0 0</pose>
          <mass>1.1</mass>
          <inertia>
            <ixx>0.00387415</ixx>
            <ixy>-0.0009</ixy>
            <ixz>0</ixz>
            <iyy>0.00387415</iyy>
            <iyz>0</iyz>
            <izz>0.002</izz>
          </inertia>
        </inertial>
        <collision name='panda_link7_collision'>
          <pose frame=''>0 0 0 0 -0 0</pose>
          <geometry>
            <mesh>
              <scale>1 1 1</scale>
              <uri>/home/bionicdl/catkin_ws/src/franka_ros/franka_description/meshes/collision/link7.stl</uri>
            </mesh>
          </geometry>
          <surface>
            <contact>
              <ode/>
            </contact>
            <friction>
              <ode/>
              <torsional>
                <ode/>
              </torsional>
            </friction>
            <bounce/>
          </surface>
          <max_contacts>10</max_contacts>
        </collision>
        <collision name='panda_link7_fixed_joint_lump__panda_hand_collision_1'>
          <pose frame=''>0 0 0.107 0 0 -0.785398</pose>
          <geometry>
            <mesh>
              <scale>1 1 1</scale>
              <uri>/home/bionicdl/catkin_ws/src/franka_ros/franka_description/meshes/collision/hand.stl</uri>
            </mesh>
          </geometry>
          <surface>
            <contact>
              <ode/>
            </contact>
            <friction>
              <ode>
                <mu>0.2</mu>
                <mu2>0.2</mu2>
              </ode>
              <torsional>
                <ode/>
              </torsional>
            </friction>
            <bounce/>
          </surface>
          <max_contacts>10</max_contacts>
        </collision>
        <visual name='panda_link7_visual'>
          <pose frame=''>0 0 0 0 -0 0</pose>
          <geometry>
            <mesh>
              <scale>1 1 1</scale>
              <uri>/home/bionicdl/catkin_ws/src/franka_ros/franka_description/meshes/visual/link7.dae</uri>
            </mesh>
          </geometry>
          <material>
            <script>
              <uri>__default__</uri>
              <name>__default__</name>
            </script>
          </material>
        </visual>
        <visual name='panda_link7_fixed_joint_lump__panda_hand_visual_1'>
          <pose frame=''>0 0 0.107 0 0 -0.785398</pose>
          <geometry>
            <mesh>
              <scale>1 1 1</scale>
              <uri>/home/bionicdl/catkin_ws/src/franka_ros/franka_description/meshes/visual/hand.dae</uri>
            </mesh>
          </geometry>
          <material>
            <script>
              <uri>__default__</uri>
              <name>__default__</name>
            </script>
          </material>
        </visual>
        <velocity_decay/>
        <gravity>0</gravity>
        <velocity_decay/>
        <self_collide>0</self_collide>
        <kinematic>0</kinematic>
      </link>
      <joint name='panda_joint7' type='revolute'>
        <child>panda_link7</child>
        <parent>panda_link6</parent>
        <axis>
          <xyz>0 0 -1</xyz>
          <limit>
            <lower>-2.8973</lower>
            <upper>2.8973</upper>
            <effort>12</effort>
            <velocity>2.61</velocity>
          </limit>
          <dynamics>
            <spring_reference>0</spring_reference>
            <spring_stiffness>0</spring_stiffness>
          </dynamics>
          <use_parent_model_frame>1</use_parent_model_frame>
        </axis>
      </joint>
      <link name='panda_leftfinger'>
        <pose frame=''>0.088 -0 0.8676 3.14159 -0 0.785398</pose>
        <inertial>
          <pose frame=''>0 0 0 0 -0 0</pose>
          <mass>0.1</mass>
          <inertia>
            <ixx>0.002</ixx>
            <ixy>0</ixy>
            <ixz>0</ixz>
            <iyy>0.0002</iyy>
            <iyz>0</iyz>
            <izz>0.0002</izz>
          </inertia>
        </inertial>
        <collision name='panda_leftfinger_collision'>
          <pose frame=''>0 0 0 0 -0 0</pose>
          <geometry>
            <mesh>
              <scale>1 1 1</scale>
              <uri>/home/bionicdl/catkin_ws/src/franka_ros/franka_description/meshes/collision/finger.stl</uri>
            </mesh>
          </geometry>
          <surface>
            <contact>
              <ode/>
            </contact>
            <friction>
              <ode/>
              <torsional>
                <ode/>
              </torsional>
            </friction>
            <bounce/>
          </surface>
          <max_contacts>10</max_contacts>
        </collision>
        <visual name='panda_leftfinger_visual'>
          <pose frame=''>0 0 0 0 -0 0</pose>
          <geometry>
            <mesh>
              <scale>1 1 1</scale>
              <uri>/home/bionicdl/catkin_ws/src/franka_ros/franka_description/meshes/visual/finger.dae</uri>
            </mesh>
          </geometry>
          <material>
            <script>
              <uri>__default__</uri>
              <name>__default__</name>
            </script>
          </material>
        </visual>
        <gravity>0</gravity>
        <velocity_decay/>
        <self_collide>0</self_collide>
        <kinematic>0</kinematic>
      </link>
      <joint name='panda_finger_joint1' type='prismatic'>
        <child>panda_leftfinger</child>
        <parent>panda_link7</parent>
        <axis>
          <xyz>0.707107 -0.707107 0</xyz>
          <limit>
            <lower>0</lower>
            <upper>0.04</upper>
            <effort>20</effort>
            <velocity>0.2</velocity>
          </limit>
          <dynamics>
            <spring_reference>0</spring_reference>
            <spring_stiffness>0</spring_stiffness>
          </dynamics>
          <use_parent_model_frame>1</use_parent_model_frame>
        </axis>
      </joint>
      <link name='panda_rightfinger'>
        <pose frame=''>0.088 -0 0.8676 3.14159 -0 0.785398</pose>
        <inertial>
          <pose frame=''>0 0 0 0 -0 0</pose>
          <mass>0.1</mass>
          <inertia>
            <ixx>0.002</ixx>
            <ixy>0</ixy>
            <ixz>0</ixz>
            <iyy>0.0002</iyy>
            <iyz>0</iyz>
            <izz>0.0002</izz>
          </inertia>
        </inertial>
        <collision name='panda_rightfinger_collision'>
          <pose frame=''>0 0 0 0 -0 -3.14159</pose>
          <geometry>
            <mesh>
              <scale>1 1 1</scale>
              <uri>/home/bionicdl/catkin_ws/src/franka_ros/franka_description/meshes/collision/finger.stl</uri>
            </mesh>
          </geometry>
          <surface>
            <contact>
              <ode>
                <kp>1e+06</kp>
                <kd>1</kd>
              </ode>
            </contact>
            <friction>
              <ode>
                <mu>30</mu>
                <mu2>30</mu2>
              </ode>
              <torsional>
                <ode/>
              </torsional>
            </friction>
            <bounce/>
          </surface>
          <max_contacts>10</max_contacts>
        </collision>
        <visual name='panda_rightfinger_visual'>
          <pose frame=''>0 0 0 0 -0 -3.14159</pose>
          <geometry>
            <mesh>
              <scale>1 1 1</scale>
              <uri>/home/bionicdl/catkin_ws/src/franka_ros/franka_description/meshes/visual/finger.dae</uri>
            </mesh>
          </geometry>
          <material>
            <script>
              <uri>__default__</uri>
              <name>__default__</name>
            </script>
          </material>
        </visual>
        <gravity>0</gravity>
        <velocity_decay/>
        <self_collide>0</self_collide>
        <kinematic>0</kinematic>
      </link>
      <joint name='panda_finger_joint2' type='prismatic'>
        <child>panda_rightfinger</child>
        <parent>panda_link7</parent>
        <axis>
          <xyz>-0.707107 0.707107 -0</xyz>
          <limit>
            <lower>0</lower>
            <upper>0.04</upper>
            <effort>20</effort>
            <velocity>0.2</velocity>
          </limit>
          <dynamics>
            <spring_reference>0</spring_reference>
            <spring_stiffness>0</spring_stiffness>
          </dynamics>
          <use_parent_model_frame>1</use_parent_model_frame>
        </axis>
      </joint>
      <static>0</static>
      <plugin name='gazebo_ros_control' filename='libgazebo_ros_control.so'>
        <robotSimType>gazebo_ros_control/DefaultRobotHWSim</robotSimType>
        <robotNamespace>/</robotNamespace>
      </plugin>
      <pose frame=''>0 0 0 0 -0 0</pose>
    </model>
    <model name='snacks'>
      <link name='snacks_link'>
        <inertial>
          <pose frame=''>0 0 0 0 -0 0</pose>
          <mass>0.08</mass>
          <inertia>
            <ixx>1</ixx>
            <ixy>0</ixy>
            <ixz>0</ixz>
            <iyy>1</iyy>
            <iyz>0</iyz>
            <izz>1</izz>
          </inertia>
        </inertial>
        <visual name='snacks_visual'>
          <pose frame=''>0 0 0 0 -0 0</pose>
          <material>
            <script>
              <uri>model://snacks/materials/scripts</uri>
              <uri>model://snacks/materials/textures</uri>
              <name>snacks</name>
            </script>
          </material>
          <geometry>
            <mesh>
              <uri>model://snacks/meshes/snacks.dae</uri>
              <scale>1 1 1</scale>
            </mesh>
          </geometry>
        </visual>
        <collision name='snacks_collision'>
          <pose frame=''>0.04 0.02 0.117 0 -0 2.1</pose>
          <geometry>
            <box>
              <size>0.165 0.06 0.235</size>
            </box>
          </geometry>
          <max_contacts>10</max_contacts>
          <surface>
            <contact>
              <ode/>
            </contact>
            <bounce/>
            <friction>
              <torsional>
                <ode/>
              </torsional>
              <ode/>
            </friction>
          </surface>
        </collision>
        <self_collide>0</self_collide>
        <kinematic>0</kinematic>
        <gravity>1</gravity>
      </link>
      <pose frame=''>0.599109 -0.203835 0 0 -0 0</pose>
    </model>
    <model name='biscuits'>
      <link name='biscuits_link'>
        <inertial>
          <pose frame=''>0 0 0 0 -0 0</pose>
          <mass>0.1</mass>
          <inertia>
            <ixx>1</ixx>
            <ixy>0</ixy>
            <ixz>0</ixz>
            <iyy>1</iyy>
            <iyz>0</iyz>
            <izz>1</izz>
          </inertia>
        </inertial>
        <visual name='biscuits_visual'>
          <pose frame=''>0 0 0 0 -0 0</pose>
          <material>
            <script>
              <uri>model://biscuits/materials/scripts</uri>
              <uri>model://biscuits/materials/textures</uri>
              <name>biscuits</name>
            </script>
          </material>
          <geometry>
            <mesh>
              <uri>model://biscuits/meshes/biscuits.dae</uri>
              <scale>1 1 1</scale>
            </mesh>
          </geometry>
        </visual>
        <collision name='biscuits_collision'>
          <pose frame=''>0.015 0.01 0.075 0 -0 2.2</pose>
          <geometry>
            <box>
              <size>0.19 0.06 0.15</size>
            </box>
          </geometry>
          <max_contacts>10</max_contacts>
          <surface>
            <contact>
              <ode/>
            </contact>
            <bounce/>
            <friction>
              <torsional>
                <ode/>
              </torsional>
              <ode/>
            </friction>
          </surface>
        </collision>
        <self_collide>0</self_collide>
        <kinematic>0</kinematic>
        <gravity>1</gravity>
      </link>
      <pose frame=''>0.599146 0.09471 0 0 -0 0</pose>
    </model>
    <model name='soap'>
      <link name='soap_link'>
        <inertial>
          <pose frame=''>0 0 0 0 -0 0</pose>
          <mass>0.08</mass>
          <inertia>
            <ixx>1</ixx>
            <ixy>0</ixy>
            <ixz>0</ixz>
            <iyy>1</iyy>
            <iyz>0</iyz>
            <izz>1</izz>
          </inertia>
        </inertial>
        <visual name='soap_visual'>
          <pose frame=''>0 0 0 0 -0 0</pose>
          <material>
            <script>
              <uri>model://soap/materials/scripts</uri>
              <uri>model://soap/materials/textures</uri>
              <name>soap</name>
            </script>
          </material>
          <geometry>
            <mesh>
              <uri>model://soap/meshes/soap.dae</uri>
              <scale>1 1 1</scale>
            </mesh>
          </geometry>
        </visual>
        <collision name='soap_collision'>
          <pose frame=''>0.02 0.002 0.05 0 0 -1.05</pose>
          <geometry>
            <box>
              <size>0.14 0.065 0.1</size>
            </box>
          </geometry>
          <max_contacts>10</max_contacts>
          <surface>
            <contact>
              <ode/>
            </contact>
            <bounce/>
            <friction>
              <torsional>
                <ode/>
              </torsional>
              <ode/>
            </friction>
          </surface>
        </collision>
        <self_collide>0</self_collide>
        <kinematic>0</kinematic>
        <gravity>1</gravity>
      </link>
      <pose frame=''>0.854245 -0.030165 0 0 -0 0</pose>
    </model>
    <model name='dropbox'>
      <link name='link_0'>
        <pose frame=''>0 -0 0 0 0 -1.56873</pose>
        <inertial>
          <mass>1</mass>
          <inertia>
            <ixx>0.166667</ixx>
            <ixy>0</ixy>
            <ixz>0</ixz>
            <iyy>0.166667</iyy>
            <iyz>0</iyz>
            <izz>0.166667</izz>
          </inertia>
        </inertial>
        <visual name='visual'>
          <pose frame=''>0 0 0 0 -0 0</pose>
          <geometry>
            <mesh>
              <uri>model://dropbox/meshes/dropbox.dae</uri>
              <scale>1 1 1</scale>
            </mesh>
          </geometry>
          <material>
            <lighting>1</lighting>
            <script>
              <uri>file://media/materials/scripts/gazebo.material</uri>
              <name>Gazebo/Grey</name>
            </script>
            <ambient>0.3 0.3 0.3 1</ambient>
            <diffuse>0.7 0.7 0.7 1</diffuse>
            <specular>0.01 0.01 0.01 1</specular>
            <emissive>0 0 0 1</emissive>
          </material>
          <transparency>0</transparency>
          <cast_shadows>1</cast_shadows>
        </visual>
        <collision name='collision'>
          <laser_retro>0</laser_retro>
          <max_contacts>10</max_contacts>
          <pose frame=''>0 0 0 0 -0 0</pose>
          <geometry>
            <mesh>
              <uri>model://dropbox/meshes/dropbox.dae</uri>
              <scale>1 1 1</scale>
            </mesh>
          </geometry>
          <surface>
            <friction>
              <ode>
                <mu>1</mu>
                <mu2>1</mu2>
                <fdir1>0 0 0</fdir1>
                <slip1>0</slip1>
                <slip2>0</slip2>
              </ode>
              <torsional>
                <coefficient>1</coefficient>
                <patch_radius>0</patch_radius>
                <surface_radius>0</surface_radius>
                <use_patch_radius>1</use_patch_radius>
                <ode>
                  <slip>0</slip>
                </ode>
              </torsional>
            </friction>
            <bounce>
              <restitution_coefficient>0</restitution_coefficient>
              <threshold>1e+06</threshold>
            </bounce>
            <contact>
              <collide_without_contact>0</collide_without_contact>
              <collide_without_contact_bitmask>1</collide_without_contact_bitmask>
              <collide_bitmask>1</collide_bitmask>
              <ode>
                <soft_cfm>0</soft_cfm>
                <soft_erp>0.2</soft_erp>
                <kp>1e+13</kp>
                <kd>1</kd>
                <max_vel>0.01</max_vel>
                <min_depth>0</min_depth>
              </ode>
              <bullet>
                <split_impulse>1</split_impulse>
                <split_impulse_penetration_threshold>-0.01</split_impulse_penetration_threshold>
                <soft_cfm>0</soft_cfm>
                <soft_erp>0.2</soft_erp>
                <kp>1e+13</kp>
                <kd>1</kd>
              </bullet>
            </contact>
          </surface>
        </collision>
        <self_collide>0</self_collide>
        <kinematic>0</kinematic>
        <gravity>1</gravity>
      </link>
      <static>1</static>
      <allow_auto_disable>1</allow_auto_disable>
      <pose frame=''>-0.2 -0.75 0 0 -0 0</pose>
    </model>
    <state world_name='default'>
      <sim_time>182 3000000</sim_time>
      <real_time>86 24905836</real_time>
      <wall_time>1543225498 826286422</wall_time>
      <iterations>82662</iterations>
      <model name='biscuits'>
        <pose frame=''>0.599146 0.09471 0 0 -0 0</pose>
        <scale>1 1 1</scale>
        <link name='biscuits_link'>
          <pose frame=''>0.599146 0.09471 0 0 -0 0</pose>
          <velocity>0 0 0 0 -0 0</velocity>
          <acceleration>0 0 0.027885 0.067962 0.064041 0</acceleration>
          <wrench>0 0 0.002788 0 -0 0</wrench>
        </link>
      </model>
      <model name='dropbox'>
        <pose frame=''>-0.2 -0.75 0 0 -0 0</pose>
        <scale>1 1 1</scale>
        <link name='link_0'>
          <pose frame=''>-0.2 -0.75 0 0 0 -1.56873</pose>
          <velocity>0 0 0 0 -0 0</velocity>
          <acceleration>0 0 0 0 -0 0</acceleration>
          <wrench>0 0 0 0 -0 0</wrench>
        </link>
      </model>
      <model name='ground_plane'>
        <pose frame=''>0 0 0 0 -0 0</pose>
        <scale>1 1 1</scale>
        <link name='link'>
          <pose frame=''>0 0 0 0 -0 0</pose>
          <velocity>0 0 0 0 -0 0</velocity>
          <acceleration>0 0 0 0 -0 0</acceleration>
          <wrench>0 0 0 0 -0 0</wrench>
        </link>
      </model>
      <model name='robot'>
        <pose frame=''>0 0 0 0 -0 0</pose>
        <scale>1 1 1</scale>
        <link name='camera_link'>
          <pose frame=''>0.6 0 1.2 0 1.57 0</pose>
          <velocity>0 0 0 0 -0 0</velocity>
          <acceleration>0 0 0 0 -0 0</acceleration>
          <wrench>0 0 0 0 -0 0</wrench>
        </link>
        <link name='panda_leftfinger'>
          <pose frame=''>0.541514 -9e-06 0.387231 3.13878 0.065745 -0.042663</pose>
          <velocity>-0.000487 -4.4e-05 -0.000227 0.041675 0.001469 -0.01684</velocity>
          <acceleration>-0.487328 -0.044261 -0.2274 -0.957356 -1.51731 1.35906</acceleration>
          <wrench>-0.048733 -0.004426 -0.02274 0 -0 0</wrench>
        </link>
        <link name='panda_link0'>
          <pose frame=''>-1e-06 0 1.5e-05 -0.000235 7e-06 -8e-06</pose>
          <velocity>3.5e-05 7e-06 8.8e-05 -0.150592 0.000551 -0.000146</velocity>
          <acceleration>0.726987 0.019346 1.47646 1.92656 1.53697 -1.50399</acceleration>
          <wrench>2.18096 0.058039 4.42938 0 -0 0</wrench>
        </link>
        <link name='panda_link1'>
          <pose frame=''>2e-06 4.2e-05 0.333015 -5.7e-05 5e-06 -6.3e-05</pose>
          <velocity>8e-05 0.019588 8.8e-05 0.005637 0.000105 0.005217</velocity>
          <acceleration>0.079694 19.5883 0.087909 -0.646659 0.104881 -1.06646</acceleration>
          <wrench>0.239082 58.7649 0.263728 0 -0 0</wrench>
        </link>
        <link name='panda_link2'>
          <pose frame=''>2e-06 4.1e-05 0.333015 -1.57084 -1.6e-05 -5.8e-05</pose>
          <velocity>7.8e-05 0.019041 9e-05 0.027979 8.6e-05 -0.002026</velocity>
          <acceleration>0.077762 19.0405 0.089934 2.84652 0.449463 -0.395493</acceleration>
          <wrench>0.233286 57.1215 0.269801 0 -0 0</wrench>
        </link>
        <link name='panda_link3'>
          <pose frame=''>-4e-06 4.9e-05 0.649015 -2.3e-05 -1.7e-05 -0.00011</pose>
          <velocity>1.5e-05 0.006122 9.2e-05 0.042972 -0.000166 -0.000325</velocity>
          <acceleration>0.014526 6.12167 0.092079 -1.01016 -0.16647 -0.324486</acceleration>
          <wrench>0.029051 12.2433 0.184158 0 -0 0</wrench>
        </link>
        <link name='panda_link4'>
          <pose frame=''>0.082496 3.8e-05 0.649017 -1.57074 1.12547 3.14153</pose>
          <velocity>1.3e-05 0.004664 0.000111 0.043339 0.000514 -0.016148</velocity>
          <acceleration>0.012872 4.66398 0.11071 -0.642945 0.41755 -0.961838</acceleration>
          <wrench>0.025744 9.32797 0.221419 0 -0 0</wrench>
        </link>
        <link name='panda_link5'>
          <pose frame=''>0.464582 -2e-06 0.55806 -3.14157 1.12547 3.14152</pose>
          <velocity>-5.1e-05 -0.000856 -0.000163 0.041576 0.000974 -0.019835</velocity>
          <acceleration>-0.05139 -0.855627 -0.163288 -1.42714 0.952183 -1.32551</acceleration>
          <wrench>-0.102779 -1.71125 -0.326576 0 -0 0</wrench>
        </link>
        <link name='panda_link6'>
          <pose frame=''>0.464582 -2e-06 0.55806 1.57079 0.065811 -9.4e-05</pose>
          <velocity>-5.4e-05 -0.00089 -0.000163 0.041724 0.000973 -0.019249</velocity>
          <acceleration>-0.053983 -0.889551 -0.163034 -2.25792 0.936682 -1.14003</acceleration>
          <wrench>-0.107967 -1.7791 -0.326068 0 -0 0</wrench>
        </link>
        <link name='panda_link7'>
          <pose frame=''>0.552391 -1e-05 0.552273 3.09308 0.044489 -0.829048</pose>
          <velocity>-6.3e-05 -0.002247 -0.000254 0.041789 0.001114 -0.017449</velocity>
          <acceleration>-0.073842 -1.83 -0.253494 -1.39712 0.780337 1.35332</acceleration>
          <wrench>-0.081226 -2.013 -0.278843 0 -0 0</wrench>
        </link>
        <link name='panda_rightfinger'>
          <pose frame=''>0.54152 0.000125 0.38723 3.13878 0.065746 -0.042663</pose>
          <velocity>-0.00048 -0.000133 -0.000222 0.041715 0.00141 -0.016905</velocity>
          <acceleration>-0.480111 -0.132969 -0.221978 2.20328 -1.44998 -2.02557</acceleration>
          <wrench>-0.048011 -0.013297 -0.022198 0 -0 0</wrench>
        </link>
      </model>
      <model name='snacks'>
        <pose frame=''>0.599101 -0.203839 8.1e-05 0.014478 -0.024762 -0.000179</pose>
        <scale>1 1 1</scale>
        <link name='snacks_link'>
          <pose frame=''>0.599101 -0.203839 8.1e-05 0.014478 -0.024762 -0.000179</pose>
          <velocity>0 0 0 0 -0 0</velocity>
          <acceleration>3e-06 -4e-06 -0.005129 0.05961 0.021579 0</acceleration>
          <wrench>0 0 -0.00041 0 -0 0</wrench>
        </link>
      </model>
      <model name='soap'>
        <pose frame=''>0.854245 -0.030165 0 1e-06 -1e-06 0</pose>
        <scale>1 1 1</scale>
        <link name='soap_link'>
          <pose frame=''>0.854245 -0.030165 0 1e-06 -1e-06 0</pose>
          <velocity>0 0 0 0 -0 0</velocity>
          <acceleration>0 0 -0.004951 -0.058685 -0.020874 0</acceleration>
          <wrench>0 0 -0.000396 0 -0 0</wrench>
        </link>
      </model>
      <light name='sun'>
        <pose frame=''>0 0 10 0 -0 0</pose>
      </light>
    </state>
    <gui fullscreen='0'>
      <camera name='user_camera'>
        <pose frame=''>7.30931 -4e-06 0.038266 -0 0.008179 3.14159</pose>
        <view_controller>orbit</view_controller>
        <projection_type>perspective</projection_type>
      </camera>
    </gui>
  </world>
</sdf>
